<?xml version="1.0" ?>
<!-- =================================================================================== -->
<!-- |    This document was autogenerated by xacro from ./pedro_description/pedro.urdf.xacro | -->
<!-- |    EDITING THIS FILE BY HAND IS NOT RECOMMENDED                                 | -->
<!-- =================================================================================== -->
<robot name="Pedro">
  <!-- Size of square 'camera' box -->
  <!-- ros_control plugin -->
  <gazebo>
    <plugin filename="libgazebo_ros_control.so" name="gazebo_ros_control">
      <robotNamespace>/pedro</robotNamespace>
    </plugin>
  </gazebo>
  <!-- Chassis -->
  <gazebo reference="chassis">
    <material>Gazebo/Orange</material>
    <gravity>True</gravity>
    <mu1>0.2</mu1>
    <mu2>0.2</mu2>
  </gazebo>
  <!-- FR_wheel -->
  <gazebo reference="FR_wheel">
    <material>Gazebo/Blue</material>
    <gravity>True</gravity>
    <mu1>0.2</mu1>
    <mu2>0.2</mu2>
  </gazebo>
  <!-- FL_wheel -->
  <gazebo reference="FL_wheel">
    <material>Gazebo/Blue</material>
    <gravity>True</gravity>
    <mu1>0.2</mu1>
    <mu2>0.2</mu2>
  </gazebo>
  <!-- BR_wheel -->
  <gazebo reference="BR_wheel">
    <material>Gazebo/Blue</material>
    <gravity>True</gravity>
    <mu1>0.2</mu1>
    <mu2>0.2</mu2>
  </gazebo>
  <!-- BL_wheel -->
  <gazebo reference="BL_wheel">
    <material>Gazebo/Blue</material>
    <gravity>True</gravity>
    <mu1>0.2</mu1>
    <mu2>0.2</mu2>
  </gazebo>
  <!-- camera -->
  <gazebo reference="camera_link">
    <sensor name="camera1" type="camera">
      <update_rate>30.0</update_rate>
      <camera name="head">
        <horizontal_fov>1.3962634</horizontal_fov>
        <image>
          <width>800</width>
          <height>800</height>
          <format>R8G8B8</format>
        </image>
        <clip>
          <near>0.02</near>
          <far>300</far>
        </clip>
        <noise>
          <type>gaussian</type>
          <!-- Noise is sampled independently per pixel on each frame.
                     That pixel's noise value is added to each of its color
                     channels, which at that point lie in the range [0,1]. -->
          <mean>0.0</mean>
          <stddev>0.007</stddev>
        </noise>
      </camera>
      <plugin filename="libgazebo_ros_camera.so" name="camera_controller">
        <alwaysOn>true</alwaysOn>
        <updateRate>0.0</updateRate>
        <cameraName>rrbot/camera1</cameraName>
        <imageTopicName>image_raw</imageTopicName>
        <cameraInfoTopicName>camera_info</cameraInfoTopicName>
        <frameName>camera_link_optical</frameName>
        <!-- setting hackBaseline to anything but 0.0 will cause a misalignment
                  between the gazebo sensor image and the frame it is supposed to
                  be attached to -->
        <hackBaseline>0.0</hackBaseline>
        <distortionK1>0.0</distortionK1>
        <distortionK2>0.0</distortionK2>
        <distortionK3>0.0</distortionK3>
        <distortionT1>0.0</distortionT1>
        <distortionT2>0.0</distortionT2>
        <CxPrime>0</CxPrime>
        <Cx>0.0</Cx>
        <Cy>0.0</Cy>
        <focalLength>0.0</focalLength>
      </plugin>
    </sensor>
  </gazebo>
  <!-- hokuyo -->
  <gazebo reference="hokuyo_link">
    <sensor name="head_hokuyo_sensor" type="gpu_ray">
      <pose>0 0 0 0 0 0</pose>
      <visualize>false</visualize>
      <update_rate>40</update_rate>
      <ray>
        <scan>
          <horizontal>
            <samples>720</samples>
            <resolution>1</resolution>
            <min_angle>-1.570796</min_angle>
            <max_angle>1.570796</max_angle>
          </horizontal>
        </scan>
        <range>
          <min>0.10</min>
          <max>30.0</max>
          <resolution>0.01</resolution>
        </range>
        <noise>
          <type>gaussian</type>
          <!-- Noise parameters based on published spec for Hokuyo laser
                  achieving "+-30mm" accuracy at range < 10m.  A mean of 0.0m and
                  stddev of 0.01m will put 99.7% of samples within 0.03m of the true
                  reading. -->
          <mean>0.0</mean>
          <stddev>0.01</stddev>
        </noise>
      </ray>
      <plugin filename="libgazebo_ros_gpu_laser.so" name="gazebo_ros_head_hokuyo_controller">
        <topicName>/rrbot/laser/scan</topicName>
        <frameName>hokuyo_link</frameName>
      </plugin>
    </sensor>
  </gazebo>
  <material name="black">
    <color rgba="0.0 0.0 0.0 1.0"/>
  </material>
  <material name="blue">
    <color rgba="0.0 0.0 0.8 1.0"/>
  </material>
  <material name="green">
    <color rgba="0.0 0.8 0.0 1.0"/>
  </material>
  <material name="grey">
    <color rgba="0.2 0.2 0.2 1.0"/>
  </material>
  <material name="orange">
    <color rgba="1.0 0.4235294117647059 0.0392156862745098 1.0"/>
  </material>
  <material name="brown">
    <color rgba="0.8705882352941177 0.8117647058823529 0.7647058823529411 1.0"/>
  </material>
  <material name="red">
    <color rgba="0.8 0.0 0.0 1.0"/>
  </material>
  <material name="white">
    <color rgba="1.0 1.0 1.0 1.0"/>
  </material>
  <!-- <xacro:macro name="wheel" params="mass radius width xgap ygap zoff reflectX reflectY">
        <xacro:cylinder_inertial radius="radius" length="width" mass="mass">
            <xacro:if value="reflectX == True">
                <origin xyz="{reflectX*xgap} ygap zoff" rpy="0 ${PI/2} ${PI/2}"/>
            </xacro:if>
            <xacro:if value="reflectY == True">
                <origin xyz="xgap {reflectY*ygap} zoff" rpy="0 ${PI/2} ${PI/2}"/>
            </xacro:if>
            <xacro:if value="reflectX == True">
                <xacro:if value="reflectY == True">
                    <origin xyz="{reflectX*xgap}  {reflectX*ygap} zoff" rpy="0 ${PI/2} ${PI/2}"/>
                </xacro:if>
            </xacro:if>
            <xacro:if value="reflectX == False">
                <xacro:if value="reflectY == False">
                    <origin xyz="{xgap}  {ygap} zoff" rpy="0 ${PI/2} ${PI/2}"/>
                </xacro:if>
            </xacro:if>
        </xacro:cylinder_inertial>
        
        <collision>
            <origin xyz="${wheel_xgap} ${wheel_ygap} ${wheel_zoff}" rpy="0 ${PI/2} ${PI/2}"/>
            <geometry>
                <cylinder radius="${wheel_radius}" length="${wheel_width}"/>
            </geometry>
        </collision>
        <visual>
            <origin xyz="${wheel_xgap} ${wheel_ygap} ${wheel_zoff}" rpy="0 ${PI/2} ${PI/2}"/>
            <geometry>
                <cylinder radius="${wheel_radius}" length="${wheel_width}"/>
            </geometry>
        </visual>
    </xacro:macro> -->
  <link name="chassis">
    <origin rpy="0 0 0" xyz="0.0 0.0 0"/>
    <inertial>
      <mass value="1"/>
      <inertia ixx="0.003541665250000001" ixy="0.0" ixz="0.0" iyy="0.016666660000000003" iyz="0.0" izz="0.013541661250000003"/>
    </inertial>
    <collision>
      <origin rpy="0 0 0" xyz="0.0 0.0 0"/>
      <geometry>
        <box size="0.4 0.2 0.05"/>
      </geometry>
    </collision>
    <visual>
      <origin rpy="0 0 0" xyz="0.0 0.0 0"/>
      <geometry>
        <box size="0.4 0.2 0.05"/>
      </geometry>
      <material name="grey"/>
    </visual>
  </link>
  <joint name="FL_hinge" type="continuous">
    <parent link="chassis"/>
    <child link="FL_wheel"/>
    <origin rpy="0 0 0" xyz="0.15 0.13 0.0"/>
    <axis xyz="0 1 0"/>
    <dynamics damping="0.7"/>
  </joint>
  <!-- ${wheel_xgap} 0 ${wheel_zoff} -->
  <joint name="FR_hinge" type="continuous">
    <origin rpy="0 0 0 " xyz="0.15 -0.13 0.0"/>
    <child link="FR_wheel"/>
    <parent link="chassis"/>
    <axis xyz="0 1 0"/>
  </joint>
  <joint name="BL_hinge" type="continuous">
    <origin rpy="0 0 0" xyz="-0.15 0.13 0.0"/>
    <child link="BL_wheel"/>
    <parent link="chassis"/>
    <axis xyz="0 1 0"/>
  </joint>
  <joint name="BR_hinge" type="continuous">
    <origin rpy="0 0 0" xyz="-0.15 -0.13 0.0"/>
    <child link="BR_wheel"/>
    <parent link="chassis"/>
    <axis xyz="0 1 0"/>
  </joint>
  <link name="FL_wheel">
    <inertial>
      <mass value="0.05"/>
      <origin rpy="0 1.57075 1.57075" xyz="0 0 0"/>
      <inertia ixx="4.166665000000001e-05" ixy="0.0" ixz="0.0" iyy="4.166665000000001e-05" iyz="0.0" izz="6.250000000000001e-05"/>
    </inertial>
    <collision>
      <origin rpy="0 1.57075 1.57075" xyz="0 0 0"/>
      <geometry>
        <cylinder length="0.05" radius="0.05"/>
      </geometry>
    </collision>
    <visual>
      <origin rpy="0 1.57075 1.57075" xyz="0 0 0"/>
      <geometry>
        <cylinder length="0.05" radius="0.05"/>
      </geometry>
      <material name="blue"/>
    </visual>
  </link>
  <link name="FR_wheel">
    <inertial>
      <mass value="0.05"/>
      <origin rpy="0 1.57075 1.57075" xyz="0 0 0"/>
      <inertia ixx="4.166665000000001e-05" ixy="0.0" ixz="0.0" iyy="4.166665000000001e-05" iyz="0.0" izz="6.250000000000001e-05"/>
    </inertial>
    <collision>
      <origin rpy="0 1.57075 1.57075" xyz="0 0 0"/>
      <geometry>
        <cylinder length="0.05" radius="0.05"/>
      </geometry>
    </collision>
    <visual>
      <origin rpy="0 1.57075 1.57075" xyz="0 0 0"/>
      <geometry>
        <cylinder length="0.05" radius="0.05"/>
      </geometry>
      <material name="blue"/>
    </visual>
  </link>
  <link name="BL_wheel">
    <inertial>
      <mass value="0.05"/>
      <origin rpy="0 1.57075 1.57075" xyz="0 0 0"/>
      <inertia ixx="4.166665000000001e-05" ixy="0.0" ixz="0.0" iyy="4.166665000000001e-05" iyz="0.0" izz="6.250000000000001e-05"/>
    </inertial>
    <collision>
      <origin rpy="0 1.57075 1.57075" xyz="0 0 0"/>
      <geometry>
        <cylinder length="0.05" radius="0.05"/>
      </geometry>
    </collision>
    <visual>
      <origin rpy="0 1.57075 1.57075" xyz="0 0 0"/>
      <geometry>
        <cylinder length="0.05" radius="0.05"/>
      </geometry>
      <material name="orange"/>
    </visual>
  </link>
  <link name="BR_wheel">
    <inertial>
      <mass value="0.05"/>
      <origin rpy="0 1.57075 1.57075" xyz="0 0 0"/>
      <inertia ixx="4.166665000000001e-05" ixy="0.0" ixz="0.0" iyy="4.166665000000001e-05" iyz="0.0" izz="6.250000000000001e-05"/>
    </inertial>
    <collision>
      <origin rpy="0 1.57075 1.57075" xyz="0 0 0"/>
      <geometry>
        <cylinder length="0.05" radius="0.05"/>
      </geometry>
    </collision>
    <visual>
      <origin rpy="0 1.57075 1.57075" xyz="0 0 0"/>
      <geometry>
        <cylinder length="0.05" radius="0.05"/>
      </geometry>
      <material name="orange"/>
    </visual>
  </link>
  <joint name="front_axle_joint" type="revolute">
    <origin rpy="0 0 0" xyz="0 0 0"/>
    <child link="Front_wheel_axles"/>
    <parent link="chassis"/>
    <axis xyz="1 0 0"/>
  </joint>
  <link name="Front_wheel_axles">
    <inertial>
      <mass value="0.01"/>
      <origin rpy="0 1.57075 1.57075" xyz="0.15 0 0.0"/>
      <inertia ixx="6.2499975e-08" ixy="0.0" ixz="0.0" iyy="6.2499975e-08" iyz="0.0" izz="1.2500000000000002e-07"/>
    </inertial>
    <visual>
      <origin rpy="0 1.57075 1.57075" xyz="0.15 0 0.0"/>
      <geometry>
        <cylinder length="0.32222222222222224" radius="0.005"/>
      </geometry>
    </visual>
  </link>
  <link name="Back_wheel_axles">
    <inertial>
      <mass value="0.01"/>
      <origin rpy="0 1.57075 1.57075" xyz="-0.15 0 0.0"/>
      <inertia ixx="6.2499975e-08" ixy="0.0" ixz="0.0" iyy="6.2499975e-08" iyz="0.0" izz="1.2500000000000002e-07"/>
    </inertial>
    <visual>
      <origin rpy="0 1.57075 1.57075" xyz="-0.15 0 0.0"/>
      <geometry>
        <cylinder length="0.32222222222222224" radius="0.005"/>
      </geometry>
    </visual>
  </link>
  <joint name="back_axle_joint" type="fixed">
    <child link="Back_wheel_axles"/>
    <parent link="chassis"/>
  </joint>
  <!-- Hokuyo Laser -->
  <link name="hokuyo_link">
    <collision>
      <origin rpy="0 0 0" xyz="0 0 0.05"/>
      <geometry>
        <box size="0.1 0.1 0.1"/>
      </geometry>
    </collision>
    <visual>
      <origin rpy="0 0 0" xyz="0 0 .05"/>
      <geometry>
        <mesh filename="hokuyo.dae"/>
      </geometry>
    </visual>
    <inertial>
      <mass value="1e-5"/>
      <origin rpy="0 0 0" xyz="0 0 0"/>
      <inertia ixx="1e-6" ixy="0" ixz="0" iyy="1e-6" iyz="0" izz="1e-6"/>
    </inertial>
  </link>
  <joint name="lidar_joint" type="fixed">
    <child link="hokuyo_link"/>
    <parent link="chassis"/>
  </joint>
  <joint name="camera_joint" type="fixed">
    <axis xyz="0 1 0"/>
    <origin rpy="0 0 0" xyz="0.1 0 .05"/>
    <parent link="chassis"/>
    <child link="camera_link"/>
  </joint>
  <!-- Camera -->
  <link name="camera_link">
    <collision>
      <origin rpy="0 0 0" xyz="0 0 0"/>
      <geometry>
        <box size="0.05 0.05 0.05"/>
      </geometry>
    </collision>
    <visual>
      <origin rpy="0 0 0" xyz="0 0 0"/>
      <geometry>
        <box size="0.05 0.05 0.05"/>
      </geometry>
      <material name="red"/>
    </visual>
    <inertial>
      <mass value="1e-5"/>
      <origin rpy="0 0 0" xyz="0 0 0"/>
      <inertia ixx="1e-6" ixy="0" ixz="0" iyy="1e-6" iyz="0" izz="1e-6"/>
    </inertial>
  </link>
  <!-- generate an optical frame http://www.ros.org/reps/rep-0103.html#suffix-frames
        so that ros and opencv can operate on the camera frame correctly -->
  <joint name="camera_optical_joint" type="fixed">
    <!-- these values have to be these values otherwise the gazebo camera image
            won't be aligned properly with the frame it is supposedly originating from -->
    <origin rpy="-1.5707963267948966 0 -1.5707963267948966" xyz="0 0 0"/>
    <parent link="camera_link"/>
    <child link="camera_link_optical"/>
  </joint>
  <link name="camera_link_optical">
    </link>
</robot>
