<sdf version='1.7'>
  <model name='Pedro'>
    <link name='chassis'>
      <inertial>
        <pose>0.08 0 -0.0125 0 -0 0</pose>
        <mass>2.00002</mass>
        <inertia>
          <ixx>1.00322</ixx>
          <ixy>0</ixy>
          <ixz>0.002</ixz>
          <iyy>1.02915</iyy>
          <iyz>0</iyz>
          <izz>1.02634</izz>
        </inertia>
      </inertial>
      <collision name='chassis_collision'>
        <pose>0 0 0 0 -0 0</pose>
        <geometry>
          <box>
            <size>0.4 0.18 0.05</size>
          </box>
        </geometry>
        <surface>
          <contact>
            <ode/>
          </contact>
          <friction>
            <ode>
              <mu>0.2</mu>
              <mu2>0.2</mu2>
            </ode>
          </friction>
        </surface>
      </collision>
      <collision name='chassis_fixed_joint_lump__camera_link_collision_1'>
        <pose>0.1 0 0.55 0 -0 0</pose>
        <geometry>
          <box>
            <size>0.05 0.05 0.05</size>
          </box>
        </geometry>
        <surface>
          <contact>
            <ode/>
          </contact>
          <friction>
            <ode/>
          </friction>
        </surface>
      </collision>
      <collision name='chassis_fixed_joint_lump__front_link_collision_2'>
        <pose>0.16 0 -0.025 0 -0 0</pose>
        <geometry>
          <box>
            <size>0.04 0.18 0.0005</size>
          </box>
        </geometry>
      </collision>
      <collision name='chassis_fixed_joint_lump__hokuyo_link_collision_3'>
        <pose>0 0 0.05 0 -0 0</pose>
        <geometry>
          <box>
            <size>0.1 0.1 0.1</size>
          </box>
        </geometry>
        <surface>
          <contact>
            <ode/>
          </contact>
          <friction>
            <ode/>
          </friction>
        </surface>
      </collision>
      <visual name='chassis_visual'>
        <pose>0 0 0 0 -0 0</pose>
        <geometry>
          <box>
            <size>0.4 0.18 0.05</size>
          </box>
        </geometry>
        <material>
          <script>
            <name>Gazebo/Orange</name>
            <uri>file://media/materials/scripts/gazebo.material</uri>
          </script>
        </material>
      </visual>
      <visual name='chassis_fixed_joint_lump__camera_link_visual_1'>
        <pose>0.1 0 0.05 0 -0 0</pose>
        <geometry>
          <box>
            <size>0.05 0.05 0.05</size>
          </box>
        </geometry>
        <material>
          <script>
            <name>Gazebo/Red</name>
            <uri>file://media/materials/scripts/gazebo.material</uri>
          </script>
        </material>
      </visual>
      <visual name='chassis_fixed_joint_lump__front_link_visual_2'>
        <pose>0.16 0 -0.025 0 -0 0</pose>
        <geometry>
          <box>
            <size>0.04 0.18 0.0005</size>
          </box>
        </geometry>
      </visual>
      <visual name='chassis_fixed_joint_lump__hokuyo_link_visual_3'>
        <pose>0 0 0.05 0 -0 0</pose>
        <geometry>
          <mesh>
            <scale>1 1 1</scale>
            <uri>hokuyo.dae</uri>
          </mesh>
        </geometry>
        <material>
          <script>
            <name>Gazebo/Black</name>
            <uri>file://media/materials/scripts/gazebo.material</uri>
          </script>
        </material>
      </visual>
      <gravity>1</gravity>
      <sensor name='camera' type='depth'>
        <visualize>1</visualize>
        <update_rate>10</update_rate>
        <camera>
          <horizontal_fov>1.089</horizontal_fov>
          <image>
            <format>B8G8R8</format>
            <width>640</width>
            <height>480</height>
          </image>
          <clip>
            <near>0.05</near>
            <far>8</far>
          </clip>
        </camera>
        <plugin name='camera_controller' filename='libgazebo_ros_camera.so'>
          <frame_name>camera_link_optical</frame_name>
          <min_depth>0.1</min_depth>
          <max_depth>100.0</max_depth>
        </plugin>
        <pose>0.1 0 0.05 0 -0 0</pose>
      </sensor>
      <sensor name='laser' type='gpu_ray'>
        <visualize>1</visualize>
        <update_rate>10</update_rate>
        <ray>
          <scan>
            <horizontal>
              <samples>360</samples>
              <resolution>1</resolution>
              <min_angle>-3.14</min_angle>
              <max_angle>3.14</max_angle>
            </horizontal>
          </scan>
          <range>
            <min>0.3</min>
            <max>12</max>
          </range>
        </ray>
        <always_on>1</always_on>
        <plugin name='laser_controller' filename='libgazebo_ros_ray_sensor.so'>
          <ros>
            <argument>~/out:=scan</argument>
          </ros>
          <output_type>sensor_msgs/LaserScan</output_type>
          <frame_name>laser_frame</frame_name>
        </plugin>
        <plugin name='pc2_gpu' filename='libgazebo_ros_ray_sensor.so'>
          <ros>
            <namespace>/gpu_ray</namespace>
            <remapping>~/out:=pointcloud2</remapping>
          </ros>
          <output_type>sensor_msgs/PointCloud2</output_type>
        </plugin>
        <plugin name='pc_gpu' filename='libgazebo_ros_ray_sensor.so'>
          <ros>
            <namespace>/gpu_ray</namespace>
            <remapping>~/out:=pointcloud</remapping>
          </ros>
          <output_type>sensor_msgs/PointCloud</output_type>
        </plugin>
        <plugin name='laserscan_gpu' filename='libgazebo_ros_ray_sensor.so'>
          <ros>
            <namespace>/gpu_ray</namespace>
            <remapping>~/out:=laserscan</remapping>
          </ros>
          <output_type>sensor_msgs/LaserScan</output_type>
        </plugin>
        <plugin name='range_gpu' filename='libgazebo_ros_ray_sensor.so'>
          <ros>
            <namespace>/gpu_ray</namespace>
            <remapping>~/out:=range</remapping>
          </ros>
          <output_type>sensor_msgs/Range</output_type>
        </plugin>
        <pose>0 0 0 0 -0 0</pose>
      </sensor>
    </link>
    <joint name='BL_hinge' type='revolute'>
      <pose relative_to='chassis'>-0.15 0.13 0 0 -0 0</pose>
      <parent>chassis</parent>
      <child>BL_wheel</child>
      <axis>
        <xyz>0 1 0</xyz>
        <limit>
          <lower>-1e+16</lower>
          <upper>1e+16</upper>
        </limit>
        <dynamics>
          <spring_reference>0</spring_reference>
          <spring_stiffness>0</spring_stiffness>
        </dynamics>
      </axis>
    </joint>
    <link name='BL_wheel'>
      <pose relative_to='BL_hinge'>0 0 0 0 -0 0</pose>
      <inertial>
        <pose>0 0 0 0 1.57075 1.57075</pose>
        <mass>0.05</mass>
        <inertia>
          <ixx>4.16667e-05</ixx>
          <ixy>0</ixy>
          <ixz>0</ixz>
          <iyy>4.16667e-05</iyy>
          <iyz>0</iyz>
          <izz>6.25e-05</izz>
        </inertia>
      </inertial>
      <collision name='BL_wheel_collision'>
        <pose>0 0 0 -1.57075 1.5708 0</pose>
        <geometry>
          <cylinder>
            <length>0.05</length>
            <radius>0.05</radius>
          </cylinder>
        </geometry>
        <surface>
          <contact>
            <ode/>
          </contact>
          <friction>
            <ode>
              <mu>0.2</mu>
              <mu2>0.2</mu2>
            </ode>
          </friction>
        </surface>
      </collision>
      <visual name='BL_wheel_visual'>
        <pose>0 0 0 -1.57075 1.5708 0</pose>
        <geometry>
          <cylinder>
            <length>0.05</length>
            <radius>0.05</radius>
          </cylinder>
        </geometry>
        <material>
          <script>
            <name>Gazebo/Blue</name>
            <uri>file://media/materials/scripts/gazebo.material</uri>
          </script>
        </material>
      </visual>
      <gravity>1</gravity>
    </link>
    <joint name='BR_hinge' type='revolute'>
      <pose relative_to='chassis'>-0.15 -0.13 0 0 -0 0</pose>
      <parent>chassis</parent>
      <child>BR_wheel</child>
      <axis>
        <xyz>0 1 0</xyz>
        <limit>
          <lower>-1e+16</lower>
          <upper>1e+16</upper>
        </limit>
        <dynamics>
          <spring_reference>0</spring_reference>
          <spring_stiffness>0</spring_stiffness>
        </dynamics>
      </axis>
    </joint>
    <link name='BR_wheel'>
      <pose relative_to='BR_hinge'>0 0 0 0 -0 0</pose>
      <inertial>
        <pose>0 0 0 0 1.57075 1.57075</pose>
        <mass>0.05</mass>
        <inertia>
          <ixx>4.16667e-05</ixx>
          <ixy>0</ixy>
          <ixz>0</ixz>
          <iyy>4.16667e-05</iyy>
          <iyz>0</iyz>
          <izz>6.25e-05</izz>
        </inertia>
      </inertial>
      <collision name='BR_wheel_collision'>
        <pose>0 0 0 -1.57075 1.5708 0</pose>
        <geometry>
          <cylinder>
            <length>0.05</length>
            <radius>0.05</radius>
          </cylinder>
        </geometry>
        <surface>
          <contact>
            <ode/>
          </contact>
          <friction>
            <ode>
              <mu>0.2</mu>
              <mu2>0.2</mu2>
            </ode>
          </friction>
        </surface>
      </collision>
      <visual name='BR_wheel_visual'>
        <pose>0 0 0 -1.57075 1.5708 0</pose>
        <geometry>
          <cylinder>
            <length>0.05</length>
            <radius>0.05</radius>
          </cylinder>
        </geometry>
        <material>
          <script>
            <name>Gazebo/Blue</name>
            <uri>file://media/materials/scripts/gazebo.material</uri>
          </script>
        </material>
      </visual>
      <gravity>1</gravity>
    </link>
    <joint name='front_left_bar_joint' type='revolute'>
      <pose relative_to='chassis'>0.16 0.08 -0.025 0 -0 0</pose>
      <parent>chassis</parent>
      <child>front_left_bar_link</child>
      <axis>
        <xyz>0 0 1</xyz>
        <limit>
          <lower>-0.5</lower>
          <upper>0.5</upper>
          <effort>100</effort>
          <velocity>10</velocity>
        </limit>
        <dynamics>
          <spring_reference>0</spring_reference>
          <spring_stiffness>0</spring_stiffness>
        </dynamics>
      </axis>
    </joint>
    <link name='front_left_bar_link'>
      <pose relative_to='front_left_bar_joint'>0 0 0 0 -0 0</pose>
      <inertial>
        <pose>0 0 0 0 -0 0</pose>
        <mass>1</mass>
        <inertia>
          <ixx>1</ixx>
          <ixy>0</ixy>
          <ixz>0</ixz>
          <iyy>1</iyy>
          <iyz>0</iyz>
          <izz>1</izz>
        </inertia>
      </inertial>
      <collision name='front_left_bar_link_collision'>
        <pose>-0.05 0 0 0 -0 0</pose>
        <geometry>
          <box>
            <size>0.08 0.018 0.0005</size>
          </box>
        </geometry>
      </collision>
      <visual name='front_left_bar_link_visual'>
        <pose>-0.05 0 0 0 -0 0</pose>
        <geometry>
          <box>
            <size>0.08 0.018 0.0005</size>
          </box>
        </geometry>
      </visual>
    </link>
    <joint name='front_left_wheel_joint' type='revolute'>
      <pose relative_to='front_left_bar_link'>0 0.05 0 0 -0 0</pose>
      <parent>front_left_bar_link</parent>
      <child>FL_wheel</child>
      <axis>
        <xyz>0 1 0</xyz>
        <limit>
          <lower>-1e+16</lower>
          <upper>1e+16</upper>
        </limit>
        <dynamics>
          <spring_reference>0</spring_reference>
          <spring_stiffness>0</spring_stiffness>
        </dynamics>
      </axis>
    </joint>
    <link name='FL_wheel'>
      <pose relative_to='front_left_wheel_joint'>0 0 0 0 -0 0</pose>
      <inertial>
        <pose>0 0 0 0 1.57075 1.57075</pose>
        <mass>0.05</mass>
        <inertia>
          <ixx>4.16667e-05</ixx>
          <ixy>0</ixy>
          <ixz>0</ixz>
          <iyy>4.16667e-05</iyy>
          <iyz>0</iyz>
          <izz>6.25e-05</izz>
        </inertia>
      </inertial>
      <collision name='FL_wheel_collision'>
        <pose>0 0 0 -1.57075 1.5708 0</pose>
        <geometry>
          <cylinder>
            <length>0.05</length>
            <radius>0.05</radius>
          </cylinder>
        </geometry>
        <surface>
          <contact>
            <ode/>
          </contact>
          <friction>
            <ode>
              <mu>0.2</mu>
              <mu2>0.2</mu2>
            </ode>
          </friction>
        </surface>
      </collision>
      <visual name='FL_wheel_visual'>
        <pose>0 0 0 -1.57075 1.5708 0</pose>
        <geometry>
          <cylinder>
            <length>0.05</length>
            <radius>0.05</radius>
          </cylinder>
        </geometry>
        <material>
          <script>
            <name>Gazebo/Blue</name>
            <uri>file://media/materials/scripts/gazebo.material</uri>
          </script>
        </material>
      </visual>
      <gravity>1</gravity>
    </link>
    <joint name='front_right_bar_joint' type='revolute'>
      <pose relative_to='chassis'>0.16 -0.08 -0.025 0 -0 0</pose>
      <parent>chassis</parent>
      <child>front_right_bar_link</child>
      <axis>
        <xyz>0 0 1</xyz>
        <limit>
          <lower>-0.5</lower>
          <upper>0.5</upper>
          <effort>100</effort>
          <velocity>10</velocity>
        </limit>
        <dynamics>
          <spring_reference>0</spring_reference>
          <spring_stiffness>0</spring_stiffness>
        </dynamics>
      </axis>
    </joint>
    <link name='front_right_bar_link'>
      <pose relative_to='front_right_bar_joint'>0 0 0 0 -0 0</pose>
      <inertial>
        <pose>0 0 0 0 -0 0</pose>
        <mass>1</mass>
        <inertia>
          <ixx>1</ixx>
          <ixy>0</ixy>
          <ixz>0</ixz>
          <iyy>1</iyy>
          <iyz>0</iyz>
          <izz>1</izz>
        </inertia>
      </inertial>
      <collision name='front_right_bar_link_collision'>
        <pose>-0.05 0 0 0 -0 0</pose>
        <geometry>
          <box>
            <size>0.08 0.018 0.0005</size>
          </box>
        </geometry>
      </collision>
      <visual name='front_right_bar_link_visual'>
        <pose>-0.05 0 0 0 -0 0</pose>
        <geometry>
          <box>
            <size>0.08 0.018 0.0005</size>
          </box>
        </geometry>
      </visual>
    </link>
    <joint name='front_right_wheel_joint' type='revolute'>
      <pose relative_to='front_right_bar_link'>0 -0.05 0 0 -0 0</pose>
      <parent>front_right_bar_link</parent>
      <child>FR_wheel</child>
      <axis>
        <xyz>0 1 0</xyz>
        <limit>
          <lower>-1e+16</lower>
          <upper>1e+16</upper>
        </limit>
        <dynamics>
          <spring_reference>0</spring_reference>
          <spring_stiffness>0</spring_stiffness>
        </dynamics>
      </axis>
    </joint>
    <link name='FR_wheel'>
      <pose relative_to='front_right_wheel_joint'>0 0 0 0 -0 0</pose>
      <inertial>
        <pose>0.15 0.13 0 0 1.57075 1.57075</pose>
        <mass>0.05</mass>
        <inertia>
          <ixx>4.16667e-05</ixx>
          <ixy>0</ixy>
          <ixz>0</ixz>
          <iyy>4.16667e-05</iyy>
          <iyz>0</iyz>
          <izz>6.25e-05</izz>
        </inertia>
      </inertial>
      <collision name='FR_wheel_collision'>
        <pose>0 0 0 -1.57075 1.5708 0</pose>
        <geometry>
          <cylinder>
            <length>0.05</length>
            <radius>0.05</radius>
          </cylinder>
        </geometry>
        <surface>
          <contact>
            <ode/>
          </contact>
          <friction>
            <ode>
              <mu>0.2</mu>
              <mu2>0.2</mu2>
            </ode>
          </friction>
        </surface>
      </collision>
      <visual name='FR_wheel_visual'>
        <pose>0 0 0 -1.57075 1.5708 0</pose>
        <geometry>
          <cylinder>
            <length>0.05</length>
            <radius>0.05</radius>
          </cylinder>
        </geometry>
        <material>
          <script>
            <name>Gazebo/Blue</name>
            <uri>file://media/materials/scripts/gazebo.material</uri>
          </script>
        </material>
      </visual>
      <gravity>1</gravity>
    </link>
    <joint name='steer_joint' type='revolute'>
      <pose relative_to='chassis'>0.16 0 -0.025 0 -0 0</pose>
      <parent>chassis</parent>
      <child>steer_link</child>
      <axis>
        <xyz>0 0 1</xyz>
        <limit>
          <lower>-0.5</lower>
          <upper>0.5</upper>
          <effort>100</effort>
          <velocity>10</velocity>
        </limit>
        <dynamics>
          <spring_reference>0</spring_reference>
          <spring_stiffness>0</spring_stiffness>
        </dynamics>
      </axis>
    </joint>
    <link name='steer_link'>
      <pose relative_to='steer_joint'>0 0 0 0 -0 0</pose>
      <inertial>
        <pose>0 0 0 0 -0 0</pose>
        <mass>1</mass>
        <inertia>
          <ixx>1</ixx>
          <ixy>0</ixy>
          <ixz>0</ixz>
          <iyy>1</iyy>
          <iyz>0</iyz>
          <izz>1</izz>
        </inertia>
      </inertial>
      <collision name='steer_link_collision'>
        <pose>-0.05 0 0 0 -0 0</pose>
        <geometry>
          <box>
            <size>0.08 0.018 0.0005</size>
          </box>
        </geometry>
      </collision>
      <visual name='steer_link_visual'>
        <pose>-0.05 0 0 0 -0 0</pose>
        <geometry>
          <box>
            <size>0.08 0.018 0.0005</size>
          </box>
        </geometry>
      </visual>
    </link>
    <joint name='ackermann_joint' type='revolute'>
      <pose relative_to='steer_link'>-0.09 0 0 0 -0 0</pose>
      <parent>steer_link</parent>
      <child>ackermann_bar_link</child>
      <axis>
        <xyz>0 0 1</xyz>
        <limit>
          <lower>-0.5</lower>
          <upper>0.5</upper>
          <effort>100</effort>
          <velocity>10</velocity>
        </limit>
        <dynamics>
          <spring_reference>0</spring_reference>
          <spring_stiffness>0</spring_stiffness>
        </dynamics>
      </axis>
    </joint>
    <link name='ackermann_bar_link'>
      <pose relative_to='ackermann_joint'>0 0 0 0 -0 0</pose>
      <inertial>
        <pose>0 0 0 0 -0 0</pose>
        <mass>1</mass>
        <inertia>
          <ixx>1</ixx>
          <ixy>0</ixy>
          <ixz>0</ixz>
          <iyy>1</iyy>
          <iyz>0</iyz>
          <izz>1</izz>
        </inertia>
      </inertial>
      <collision name='ackermann_bar_link_collision'>
        <pose>0 0 0 0 -0 0</pose>
        <geometry>
          <box>
            <size>0.04 0.18 0.0005</size>
          </box>
        </geometry>
      </collision>
      <visual name='ackermann_bar_link_visual'>
        <pose>0 0 0 0 -0 0</pose>
        <geometry>
          <box>
            <size>0.04 0.18 0.0005</size>
          </box>
        </geometry>
      </visual>
    </link>
    <static>0</static>
    <plugin name='gazebo_ros_control' filename='libgazebo_ros_control.so'>
      <robotNamespace>/pedro</robotNamespace>
    </plugin>
  </model>
</sdf>
