<?xml version="1.0" ?>
<!-- =================================================================================== -->
<!-- |    This document was autogenerated by xacro from pedro.urdfv2.xacro             | -->
<!-- |    EDITING THIS FILE BY HAND IS NOT RECOMMENDED                                 | -->
<!-- =================================================================================== -->
<robot name="Pedro">
  <!-- Size of square 'camera' box -->
  <!-- ros_control plugin -->
  <gazebo>
    <plugin filename="libgazebo_ros_control.so" name="gazebo_ros_control">
      <robotNamespace>/pedro</robotNamespace>
      <!-- <legacyModeNS>true</legacyModeNS> -->
    </plugin>
  </gazebo>
  <plugin filename="libgazebo_ros_joint_state_publisher.so" name="gazebo_ros_joint_state_publisher">
    <ros>
      <namespace>/pedro</namespace>
      <argument>joint_states:=joint_states_pedro</argument>
    </ros>
    <update_rate>2</update_rate>
    <joint_name>steer_joint</joint_name>
    <joint_name>front_left_bar_joint</joint_name>
    <joint_name>front_right_bar_joint</joint_name>
    <joint_name>front_left_wheel_joint</joint_name>
    <joint_name>front_right_wheel_joint</joint_name>
    <joint_name>ackermann_joint</joint_name>
    <joint_name>ackermann_left_bar_joint</joint_name>
    <joint_name>ackermann_right_bar_joint</joint_name>
    <joint_name>back_left_wheel_joint</joint_name>
    <joint_name>back_right_wheel_joint</joint_name>
  </plugin>
  <!-- Chassis -->
  <!-- <gazebo reference="chassis">
    <material>Gazebo/Orange</material>
    <gravity>True</gravity>
    <mu1>0.2</mu1>
    <mu2>0.2</mu2>
  </gazebo> -->
  <!-- FR_wheel -->
  <!-- <gazebo reference="front_right_wheel_joint">
    <material>Gazebo/Blue</material>
    <gravity>True</gravity>
    <mu1>0.2</mu1>
    <mu2>0.2</mu2>
  </gazebo> -->
  <!-- FL_wheel -->
  <!-- <gazebo reference="front_left_wheel_joint">
    <material>Gazebo/Blue</material>
    <gravity>True</gravity>
    <mu1>0.2</mu1>
    <mu2>0.2</mu2>
  </gazebo> -->
  <!-- BR_wheel -->
  <!-- <gazebo reference="back_right_wheel_joint">
    <material>Gazebo/Blue</material>
    <gravity>True</gravity>
    <mu1>0.2</mu1>
    <mu2>0.2</mu2>
  </gazebo> -->
  <!-- BL_wheel -->
  <!-- <gazebo reference="back_left_wheel_joint">
    <material>Gazebo/Blue</material>
    <gravity>True</gravity>
    <mu1>0.2</mu1>
    <mu2>0.2</mu2>
  </gazebo> -->
  <!-- camera -->
  <gazebo reference="camera_link">
    <material>Gazebo/Red</material>
    <sensor name="camera" type="depth">
      <pose> 0 0 0 0 0 0 </pose>
      <visualize>true</visualize>
      <update_rate>10</update_rate>
      <camera>
        <horizontal_fov>1.089</horizontal_fov>
        <image>
          <format>B8G8R8</format>
          <width>640</width>
          <height>480</height>
        </image>
        <clip>
          <near>0.05</near>
          <far>8.0</far>
        </clip>
      </camera>
      <plugin filename="libgazebo_ros_camera.so" name="camera_controller">
        <frame_name>camera_link_optical</frame_name>
        <min_depth>0.1</min_depth>
        <max_depth>100.0</max_depth>
      </plugin>
    </sensor>
  </gazebo>
  <!-- hokuyo -->
  <gazebo reference="hokuyo_link">
    <material>Gazebo/Black</material>
    <sensor name="laser" type="gpu_ray">
      <pose> 0 0 0 0 0 0 </pose>
      <visualize>true</visualize>
      <update_rate>10</update_rate>
      <ray>
        <scan>
          <horizontal>
            <samples>360</samples>
            <resolution>1.0</resolution>
            <min_angle>-3.14</min_angle>
            <max_angle>3.14</max_angle>
          </horizontal>
        </scan>
        <range>
          <min>0.3</min>
          <max>12</max>
        </range>
      </ray>
      <always_on>true</always_on>
      <plugin filename="libgazebo_ros_ray_sensor.so" name="laser_controller">
        <ros>
          <argument>~/out:=scan</argument>
        </ros>
        <output_type>sensor_msgs/LaserScan</output_type>
        <frame_name>laser_frame</frame_name>
      </plugin>
      <plugin filename="libgazebo_ros_ray_sensor.so" name="pc2_gpu">
        <ros>
          <namespace>/gpu_ray</namespace>
          <remapping>~/out:=pointcloud2</remapping>
        </ros>
        <output_type>sensor_msgs/PointCloud2</output_type>
      </plugin>
      <plugin filename="libgazebo_ros_ray_sensor.so" name="pc_gpu">
        <ros>
          <namespace>/gpu_ray</namespace>
          <remapping>~/out:=pointcloud</remapping>
        </ros>
        <output_type>sensor_msgs/PointCloud</output_type>
      </plugin>
      <plugin filename="libgazebo_ros_ray_sensor.so" name="laserscan_gpu">
        <ros>
          <namespace>/gpu_ray</namespace>
          <remapping>~/out:=laserscan</remapping>
        </ros>
        <output_type>sensor_msgs/LaserScan</output_type>
      </plugin>
      <plugin filename="libgazebo_ros_ray_sensor.so" name="range_gpu">
        <ros>
          <namespace>/gpu_ray</namespace>
          <remapping>~/out:=range</remapping>
        </ros>
        <output_type>sensor_msgs/Range</output_type>
      </plugin>
    </sensor>
  </gazebo>
  <material name="black">
    <color rgba="0.0 0.0 0.0 1.0"/>
  </material>
  <material name="blue">
    <color rgba="0.0 0.0 0.8 1.0"/>
  </material>
  <material name="green">
    <color rgba="0.0 0.8 0.0 1.0"/>
  </material>
  <material name="grey">
    <color rgba="0.2 0.2 0.2 1.0"/>
  </material>
  <material name="orange">
    <color rgba="1.0 0.4235294117647059 0.0392156862745098 1.0"/>
  </material>
  <material name="brown">
    <color rgba="0.8705882352941177 0.8117647058823529 0.7647058823529411 1.0"/>
  </material>
  <material name="red">
    <color rgba="0.8 0.0 0.0 1.0"/>
  </material>
  <material name="white">
    <color rgba="1.0 1.0 1.0 1.0"/>
  </material>
  <!-- Import Wheels -->
  <!-- <xacro:include filename="wheels.xacro" /> -->
  <!-- Main body -->
  <link name="base_link">
    <inertial>
      <mass value="50.0"/>
      <origin xyz="0 0 0"/>
      <inertia ixx="1.0" ixy="0.0" ixz="0.0" iyy="1.0" iyz="0.0" izz="1.0"/>
    </inertial>
    <visual>
      <origin rpy="0 0 0" xyz="0 0 0"/>
      <geometry>
        <box size="2.0 1.0 0.1"/>
      </geometry>
      <material name="blue"/>
    </visual>
    <collision>
      <origin rpy="0 0 0" xyz="0 0 0"/>
      <geometry>
        <box size="2.0 1.0 0.1"/>
      </geometry>
    </collision>
  </link>
  <gazebo reference="base_link">
    <material>Gazebo/Blue</material>
  </gazebo>
  <!-- Front link of Ackermann -->
  <joint name="front_joint" type="fixed">
    <parent link="base_link"/>
    <child link="front_link"/>
    <origin xyz="0.8 0.0 -0.25"/>
  </joint>
  <link name="front_link">
    <inertial>
      <mass value="1.0"/>
      <origin xyz="0 0 0"/>
      <inertia ixx="1.0" ixy="0.0" ixz="0.0" iyy="1.0" iyz="0.0" izz="1.0"/>
    </inertial>
    <visual>
      <geometry>
        <box size="0.1 1.0 0.01"/>
      </geometry>
      <material name="red"/>
    </visual>
    <collision>
      <geometry>
        <box size="0.1 1.0 0.01"/>
      </geometry>
    </collision>
  </link>
  <gazebo reference="front_link">
    <material>Gazebo/Red</material>
  </gazebo>
  <!-- a link aligned with the steer direction -->
  <joint name="steer_joint" type="revolute">
    <limit effort="100" lower="-0.5" upper="0.5" velocity="10"/>
    <axis xyz="0 0 1"/>
    <parent link="front_link"/>
    <child link="steer_link"/>
    <origin rpy="0 0 0" xyz="0.0 0.0 0.0"/>
  </joint>
  <link name="steer_link">
    <inertial>
      <mass value="1.0"/>
      <origin xyz="0 0 0"/>
      <inertia ixx="1.0" ixy="0.0" ixz="0.0" iyy="1.0" iyz="0.0" izz="1.0"/>
    </inertial>
    <visual>
      <origin xyz="-0.15 0 0"/>
      <geometry>
        <box size="0.4 0.1 0.01"/>
      </geometry>
      <material name="red"/>
    </visual>
    <collision>
      <origin xyz="-0.15 0 0"/>
      <geometry>
        <box size="0.4 0.1 0.01"/>
      </geometry>
    </collision>
  </link>
  <gazebo reference="steer_link">
    <material>Gazebo/Red</material>
  </gazebo>
  <!-- the left Ackermann bar -->
  <joint name="front_left_bar_joint" type="revolute">
    <limit effort="100" lower="-0.5" upper="0.5" velocity="10"/>
    <axis xyz="0 0 1"/>
    <parent link="front_link"/>
    <child link="front_left_bar_link"/>
    <origin rpy="0 0 0" xyz="0.0 0.45 0.0"/>
  </joint>
  <link name="front_left_bar_link">
    <inertial>
      <mass value="1.0"/>
      <origin xyz="0 0 0"/>
      <inertia ixx="1.0" ixy="0.0" ixz="0.0" iyy="1.0" iyz="0.0" izz="1.0"/>
    </inertial>
    <visual>
      <origin xyz="-0.15 0 0"/>
      <geometry>
        <box size="0.4 0.1 0.01"/>
      </geometry>
      <material name="red"/>
    </visual>
    <collision>
      <origin xyz="-0.15 0 0"/>
      <geometry>
        <box size="0.4 0.1 0.01"/>
      </geometry>
    </collision>
  </link>
  <gazebo reference="front_left_bar_link">
    <material>Gazebo/Red</material>
  </gazebo>
  <!-- the right Ackermann bar -->
  <joint name="front_right_bar_joint" type="revolute">
    <limit effort="100" lower="-0.5" upper="0.5" velocity="10"/>
    <axis xyz="0 0 1"/>
    <parent link="front_link"/>
    <child link="front_right_bar_link"/>
    <origin rpy="0 0 0" xyz="0.0 -0.45 0.0"/>
  </joint>
  <link name="front_right_bar_link">
    <inertial>
      <mass value="1.0"/>
      <origin xyz="0 0 0"/>
      <inertia ixx="1.0" ixy="0.0" ixz="0.0" iyy="1.0" iyz="0.0" izz="1.0"/>
    </inertial>
    <visual>
      <origin xyz="-0.15 0 0"/>
      <geometry>
        <box size="0.4 0.1 0.01"/>
      </geometry>
      <material name="red"/>
    </visual>
    <collision>
      <origin xyz="-0.15 0 0"/>
      <geometry>
        <box size="0.4 0.1 0.01"/>
      </geometry>
    </collision>
  </link>
  <gazebo reference="front_right_bar_link">
    <material>Gazebo/Red</material>
  </gazebo>
  <!-- the front left wheel -->
  <joint name="front_left_wheel_joint" type="continuous">
    <axis xyz="0 1 0"/>
    <parent link="front_left_bar_link"/>
    <child link="front_left_wheel_link"/>
    <origin rpy="0 0 0" xyz="0 0.1 0"/>
  </joint>
  <link name="front_left_wheel_link">
    <inertial>
      <mass value="1.0"/>
      <origin xyz="0 0 0"/>
      <inertia ixx="1.0" ixy="0.0" ixz="0.0" iyy="1.0" iyz="0.0" izz="1.0"/>
    </inertial>
    <visual>
      <origin rpy="1.57079632679 0 0" xyz="0 0 0"/>
      <geometry>
        <cylinder length="0.01" radius="0.2"/>
      </geometry>
      <material name="green"/>
    </visual>
    <collision>
      <origin rpy="1.57079632679 0 0" xyz="0 0 0"/>
      <geometry>
        <cylinder length="0.01" radius="0.2"/>
      </geometry>
    </collision>
  </link>
  <gazebo reference="front_left_wheel_link">
    <material>Gazebo/Green</material>
  </gazebo>
  <!-- the front right wheel -->
  <joint name="front_right_wheel_joint" type="continuous">
    <axis xyz="0 1 0"/>
    <parent link="front_right_bar_link"/>
    <child link="front_right_wheel_link"/>
    <origin rpy="0 0 0" xyz="0 -0.1 0"/>
  </joint>
  <link name="front_right_wheel_link">
    <inertial>
      <mass value="1.0"/>
      <origin xyz="0 0 0"/>
      <inertia ixx="1.0" ixy="0.0" ixz="0.0" iyy="1.0" iyz="0.0" izz="1.0"/>
    </inertial>
    <visual>
      <origin rpy="1.57079632679 0 0" xyz="0 0 0"/>
      <geometry>
        <cylinder length="0.01" radius="0.2"/>
      </geometry>
      <material name="green"/>
    </visual>
    <collision>
      <origin rpy="1.57079632679 0 0" xyz="0 0 0"/>
      <geometry>
        <cylinder length="0.01" radius="0.2"/>
      </geometry>
    </collision>
  </link>
  <gazebo reference="front_right_wheel_link">
    <material>Gazebo/Green</material>
    <turnGravityOff>false</turnGravityOff>
  </gazebo>
  <!-- the Ackerman bar -->
  <joint name="ackermann_joint" type="revolute">
    <limit effort="100" lower="-0.5" upper="0.5" velocity="10"/>
    <axis xyz="0 0 1"/>
    <parent link="steer_link"/>
    <child link="ackermann_bar_link"/>
    <origin rpy="0 0 0" xyz="-0.3 0 0"/>
  </joint>
  <link name="ackermann_bar_link">
    <inertial>
      <mass value="1.0"/>
      <origin xyz="0 0 0"/>
      <inertia ixx="1.0" ixy="0.0" ixz="0.0" iyy="1.0" iyz="0.0" izz="1.0"/>
    </inertial>
    <visual>
      <geometry>
        <box size="0.1 1.0 0.01"/>
      </geometry>
      <material name="red"/>
    </visual>
    <collision>
      <geometry>
        <box size="0.1 1.0 0.01"/>
      </geometry>
    </collision>
  </link>
  <gazebo reference="front_link">
    <material>Gazebo/Red</material>
  </gazebo>
  <gazebo reference="ackermann_bar_link">
    <material>Gazebo/Red</material>
  </gazebo>
  <!-- Gazebo Ackermann loop joints -->
  <!-- <gazebo>
        <joint:hinge name="ackermann_left_bar_joint">
            <body1>ackermann_bar_link</body1>
            <body2>front_left_bar_link</body2>
            <anchor>ackermann_bar_link</anchor>
            <axis>0 0 1</axis>
            <anchorOffset>0 0.45 0</anchorOffset>
        </joint:hinge>
    </gazebo>
    <gazebo>
        <joint:hinge name="ackermann_right_bar_joint">
            <body1>ackermann_bar_link</body1>
            <body2>front_right_bar_link</body2>
            <anchor>ackermann_bar_link</anchor>
            <axis>0 0 1</axis>
            <anchorOffset>0 -0.45 0</anchorOffset>
        </joint:hinge>
    </gazebo> -->
  <joint name="ackermann_left_bar_joint" type="continuous">
    <axis xyz="0 0 1"/>
    <parent link="ackermann_bar_link"/>
    <child link="front_left_bar_link"/>
    <origin rpy="0 0 0" xyz="0 0.45 0"/>
  </joint>
  <joint name="ackermann_right_bar_joint" type="continuous">
    <axis xyz="0 0 1"/>
    <parent link="ackermann_bar_link"/>
    <child link="front_right_bar_link"/>
    <origin rpy="0 0 0" xyz="0 -0.45 0"/>
  </joint>
  <!-- the back left wheel -->
  <joint name="back_left_wheel_joint" type="continuous">
    <axis xyz="0 1 0"/>
    <parent link="base_link"/>
    <child link="back_left_wheel_link"/>
    <origin rpy="0 0 0" xyz="-0.8 0.55 -0.25"/>
  </joint>
  <link name="back_left_wheel_link">
    <inertial>
      <mass value="1.0"/>
      <origin xyz="0 0 0"/>
      <inertia ixx="1.0" ixy="0.0" ixz="0.0" iyy="1.0" iyz="0.0" izz="1.0"/>
    </inertial>
    <visual>
      <origin rpy="1.57079632679 0 0" xyz="0 0 0"/>
      <geometry>
        <cylinder length="0.01" radius="0.2"/>
      </geometry>
      <material name="green"/>
    </visual>
    <collision>
      <origin rpy="1.57079632679 0 0" xyz="0 0 0"/>
      <geometry>
        <cylinder length="0.01" radius="0.2"/>
      </geometry>
    </collision>
  </link>
  <gazebo reference="back_left_wheel_link">
    <material>Gazebo/Green</material>
  </gazebo>
  <!-- the back right wheel -->
  <joint name="back_right_wheel_joint" type="continuous">
    <axis xyz="0 1 0"/>
    <parent link="base_link"/>
    <child link="back_right_wheel_link"/>
    <origin rpy="0 0 0" xyz="-0.8 -0.55 -0.25"/>
  </joint>
  <link name="back_right_wheel_link">
    <inertial>
      <mass value="1.0"/>
      <origin xyz="0 0 0"/>
      <inertia ixx="1.0" ixy="0.0" ixz="0.0" iyy="1.0" iyz="0.0" izz="1.0"/>
    </inertial>
    <visual>
      <origin rpy="1.57079632679 0 0" xyz="0 0 0"/>
      <geometry>
        <cylinder length="0.01" radius="0.2"/>
      </geometry>
      <material name="green"/>
    </visual>
    <collision>
      <origin rpy="1.57079632679 0 0" xyz="0 0 0"/>
      <geometry>
        <cylinder length="0.01" radius="0.2"/>
      </geometry>
    </collision>
  </link>
  <gazebo reference="back_right_wheel_link">
    <material>Gazebo/Green</material>
  </gazebo>
  <!-- Ackermann plugin -->
  <gazebo>
    <plugin filename="libgazebo_ros_ackermann_drive.so" name="ackermann_drive">
      <ros>
        <namespace>pedro</namespace>
        <remapping>cmd_vel:=cmd_vel</remapping>
        <remapping>odom:=odom</remapping>
        <remapping>distance:=distance</remapping>
      </ros>
      <updateRate>100.0</updateRate>
      <front_left_joint>front_left_wheel_joint</front_left_joint>
      <front_right_joint>front_right_wheel_joint</front_right_joint>
      <rear_left_joint>back_left_wheel_joint</rear_left_joint>
      <rear_right_joint>back_right_wheel_joint</rear_right_joint>
      <left_steering_joint>front_left_bar_joint</left_steering_joint>
      <right_steering_joint>front_right_bar_joint</right_steering_joint>
      <steering_wheel_joint>steer_link</steering_wheel_joint>
      <!-- Max absolute steer angle for tyre in radians-->
      <!-- Any cmd_vel angular z greater than this would be capped -->
      <max_steer>0.6458</max_steer>
      <!-- Max absolute steering angle of steering wheel -->
      <max_steering_angle>7.85</max_steering_angle>
      <!-- Max absolute linear speed in m/s -->
      <max_speed>20</max_speed>
      <!-- PID tuning -->
      <left_steering_pid_gain>1500 0 1</left_steering_pid_gain>
      <left_steering_i_range>0 0</left_steering_i_range>
      <right_steering_pid_gain>1500 0 1</right_steering_pid_gain>
      <right_steering_i_range>0 0</right_steering_i_range>
      <linear_velocity_pid_gain>1000 0 1</linear_velocity_pid_gain>
      <linear_velocity_i_range>0 0</linear_velocity_i_range>
      <!-- output -->
      <publish_odom>true</publish_odom>
      <publish_odom_tf>true</publish_odom_tf>
      <publish_wheel_tf>true</publish_wheel_tf>
      <publish_distance>true</publish_distance>
      <odometry_frame>odom</odometry_frame>
    </plugin>
  </gazebo>
  <transmission name="trans_right_wheel_hing">
    <type>transmission_interface/SimpleTransmission</type>
    <joint name="front_right_wheel_joint">
      <hardwareInterface>EffortJointInterface</hardwareInterface>
    </joint>
    <actuator name="motor1">
      <hardwareInterface>EffortJointInterface</hardwareInterface>
      <mechanicalReduction>1</mechanicalReduction>
    </actuator>
  </transmission>
  <transmission name="trans_right_wheel_rotate">
    <type>transmission_interface/SimpleTransmission</type>
    <joint name="front_right_bar_joint">
      <hardwareInterface>EffortJointInterface</hardwareInterface>
    </joint>
    <actuator name="motor_right_wheel_rotate">
      <hardwareInterface>EffortJointInterface</hardwareInterface>
      <mechanicalReduction>1</mechanicalReduction>
    </actuator>
  </transmission>
  <transmission name="tran2">
    <type>transmission_interface/SimpleTransmission</type>
    <joint name="front_left_wheel_joint">
      <hardwareInterface>EffortJointInterface</hardwareInterface>
    </joint>
    <actuator name="motor2">
      <hardwareInterface>EffortJointInterface</hardwareInterface>
      <mechanicalReduction>1</mechanicalReduction>
    </actuator>
  </transmission>
  <transmission name="trans_left_wheel_rotate">
    <type>transmission_interface/SimpleTransmission</type>
    <joint name="front_left_bar_joint">
      <hardwareInterface>EffortJointInterface</hardwareInterface>
    </joint>
    <actuator name="motor_left_wheel_rotate">
      <hardwareInterface>EffortJointInterface</hardwareInterface>
      <mechanicalReduction>1</mechanicalReduction>
    </actuator>
  </transmission>
  <!-- Hokuyo Laser -->
  <link name="hokuyo_link">
    <collision>
      <origin rpy="0 0 0" xyz="0 0 0.05"/>
      <geometry>
        <box size="0.1 0.1 0.1"/>
      </geometry>
    </collision>
    <visual>
      <origin rpy="0 0 0" xyz="0 0 .05"/>
      <geometry>
        <mesh filename="hokuyo.dae"/>
      </geometry>
    </visual>
    <inertial>
      <mass value="1e-5"/>
      <origin rpy="0 0 0" xyz="0 0 0"/>
      <inertia ixx="1e-6" ixy="0" ixz="0" iyy="1e-6" iyz="0" izz="1e-6"/>
    </inertial>
  </link>
  <joint name="lidar_joint" type="fixed">
    <child link="hokuyo_link"/>
    <parent link="base_link"/>
  </joint>
  <joint name="camera_joint" type="fixed">
    <axis xyz="0 1 0"/>
    <origin rpy="0 0 0" xyz="0.1 0 .05"/>
    <parent link="base_link"/>
    <child link="camera_link"/>
  </joint>
  <!-- Camera -->
  <link name="camera_link">
    <collision>
      <origin rpy="0 0 0" xyz="0 0 0.5"/>
      <geometry>
        <box size="0.05 0.05 0.05"/>
      </geometry>
    </collision>
    <visual>
      <origin rpy="0 0 0" xyz="0 0 0"/>
      <geometry>
        <box size="0.05 0.05 0.05"/>
      </geometry>
      <material name="red"/>
    </visual>
    <inertial>
      <mass value="1e-5"/>
      <origin rpy="0 0 0" xyz="0 0 0"/>
      <inertia ixx="1e-6" ixy="0" ixz="0" iyy="1e-6" iyz="0" izz="1e-6"/>
    </inertial>
  </link>
  <!-- generate an optical frame http://www.ros.org/reps/rep-0103.html#suffix-frames
        so that ros and opencv can operate on the camera frame correctly -->
  <joint name="camera_optical_joint" type="fixed">
    <!-- these values have to be these values otherwise the gazebo camera image
            won't be aligned properly with the frame it is supposedly originating from -->
    <origin rpy="-1.5707963267948966 0 -1.5707963267948966" xyz="0 0 0"/>
    <parent link="camera_link"/>
    <child link="camera_link_optical"/>
  </joint>
  <link name="camera_link_optical">
    </link>
</robot>
