<?xml version="1.0" ?>
<!-- =================================================================================== -->
<!-- |    This document was autogenerated by xacro from pedro.urdf.xacro               | -->
<!-- |    EDITING THIS FILE BY HAND IS NOT RECOMMENDED                                 | -->
<!-- =================================================================================== -->
<robot name="Pedro">
  <!-- Size of square 'camera' box -->
  <!-- Chassis -->
  <gazebo reference="chassis">
    <material>Gazebo/Orange</material>
    <gravity>True</gravity>
    <mu1>0.2</mu1>
    <mu2>0.2</mu2>
  </gazebo>
  <!-- FR_wheel -->
  <gazebo reference="FR_wheel">
    <material>Gazebo/Blue</material>
    <gravity>True</gravity>
    <mu1>0.2</mu1>
    <mu2>0.2</mu2>
  </gazebo>
  <!-- FL_wheel -->
  <gazebo reference="FL_wheel">
    <material>Gazebo/Blue</material>
    <gravity>True</gravity>
    <mu1>0.2</mu1>
    <mu2>0.2</mu2>
  </gazebo>
  <!-- BR_wheel -->
  <gazebo reference="BR_wheel">
    <material>Gazebo/Blue</material>
    <gravity>True</gravity>
    <mu1>0.2</mu1>
    <mu2>0.2</mu2>
  </gazebo>
  <!-- BL_wheel -->
  <gazebo reference="BL_wheel">
    <material>Gazebo/Blue</material>
    <gravity>True</gravity>
    <mu1>0.2</mu1>
    <mu2>0.2</mu2>
  </gazebo>
  <!-- camera -->
  <gazebo reference="camera_link">
    <material>Gazebo/Red</material>
    <sensor name="camera" type="depth">
      <pose> 0 0 0 0 0 0 </pose>
      <visualize>true</visualize>
      <update_rate>10</update_rate>
      <camera>
        <horizontal_fov>1.089</horizontal_fov>
        <image>
          <format>B8G8R8</format>
          <width>640</width>
          <height>480</height>
        </image>
        <clip>
          <near>0.05</near>
          <far>8.0</far>
        </clip>
      </camera>
      <plugin filename="libgazebo_ros_camera.so" name="camera_controller">
        <frame_name>camera_link_optical</frame_name>
        <min_depth>0.1</min_depth>
        <max_depth>100.0</max_depth>
      </plugin>
    </sensor>
  </gazebo>
  <!-- hokuyo -->
  <gazebo reference="hokuyo_link">
    <material>Gazebo/Black</material>
    <sensor name="laser" type="gpu_ray">
      <pose> 0 0 0 0 0 0 </pose>
      <visualize>true</visualize>
      <update_rate>10</update_rate>
      <ray>
        <scan>
          <horizontal>
            <samples>360</samples>
            <resolution>1.0</resolution>
            <min_angle>-3.14</min_angle>
            <max_angle>3.14</max_angle>
          </horizontal>
        </scan>
        <range>
          <min>0.3</min>
          <max>12</max>
        </range>
      </ray>
      <always_on>true</always_on>
      <plugin filename="libgazebo_ros_ray_sensor.so" name="laser_controller">
        <ros>
          <argument>~/out:=scan</argument>
        </ros>
        <output_type>sensor_msgs/LaserScan</output_type>
        <frame_name>laser_frame</frame_name>
      </plugin>
      <plugin filename="libgazebo_ros_ray_sensor.so" name="pc2_gpu">
        <ros>
          <namespace>/gpu_ray</namespace>
          <remapping>~/out:=pointcloud2</remapping>
        </ros>
        <output_type>sensor_msgs/PointCloud2</output_type>
      </plugin>
      <plugin filename="libgazebo_ros_ray_sensor.so" name="pc_gpu">
        <ros>
          <namespace>/gpu_ray</namespace>
          <remapping>~/out:=pointcloud</remapping>
        </ros>
        <output_type>sensor_msgs/PointCloud</output_type>
      </plugin>
      <plugin filename="libgazebo_ros_ray_sensor.so" name="laserscan_gpu">
        <ros>
          <namespace>/gpu_ray</namespace>
          <remapping>~/out:=laserscan</remapping>
        </ros>
        <output_type>sensor_msgs/LaserScan</output_type>
      </plugin>
      <plugin filename="libgazebo_ros_ray_sensor.so" name="range_gpu">
        <ros>
          <namespace>/gpu_ray</namespace>
          <remapping>~/out:=range</remapping>
        </ros>
        <output_type>sensor_msgs/Range</output_type>
      </plugin>
    </sensor>
  </gazebo>
  <material name="black">
    <color rgba="0.0 0.0 0.0 1.0"/>
  </material>
  <material name="blue">
    <color rgba="0.0 0.0 0.8 1.0"/>
  </material>
  <material name="green">
    <color rgba="0.0 0.8 0.0 1.0"/>
  </material>
  <material name="grey">
    <color rgba="0.2 0.2 0.2 1.0"/>
  </material>
  <material name="orange">
    <color rgba="1.0 0.4235294117647059 0.0392156862745098 1.0"/>
  </material>
  <material name="brown">
    <color rgba="0.8705882352941177 0.8117647058823529 0.7647058823529411 1.0"/>
  </material>
  <material name="red">
    <color rgba="0.8 0.0 0.0 1.0"/>
  </material>
  <material name="white">
    <color rgba="1.0 1.0 1.0 1.0"/>
  </material>
  <!-- ros_control plugin -->
  <gazebo>
    <plugin filename="libgazebo_ros_control.so" name="gazebo_ros_control">
      <robotNamespace>/pedro</robotNamespace>
      <!-- <legacyModeNS>true</legacyModeNS> -->
    </plugin>
  </gazebo>
  <!-- <xacro:macro name="wheel" params="mass radius width xgap ygap zoff reflectX reflectY">
        <xacro:cylinder_inertial radius="radius" length="width" mass="mass">
            <xacro:if value="reflectX == True">
                <origin xyz="{reflectX*xgap} ygap zoff" rpy="0 ${PI/2} ${PI/2}"/>
            </xacro:if>
            <xacro:if value="reflectY == True">
                <origin xyz="xgap {reflectY*ygap} zoff" rpy="0 ${PI/2} ${PI/2}"/>
            </xacro:if>
            <xacro:if value="reflectX == True">
                <xacro:if value="reflectY == True">
                    <origin xyz="{reflectX*xgap}  {reflectX*ygap} zoff" rpy="0 ${PI/2} ${PI/2}"/>
                </xacro:if>
            </xacro:if>
            <xacro:if value="reflectX == False">
                <xacro:if value="reflectY == False">
                    <origin xyz="{xgap}  {ygap} zoff" rpy="0 ${PI/2} ${PI/2}"/>
                </xacro:if>
            </xacro:if>
        </xacro:cylinder_inertial>
        
        <collision>
            <origin xyz="${wheel_xgap} ${wheel_ygap} ${wheel_zoff}" rpy="0 ${PI/2} ${PI/2}"/>
            <geometry>
                <cylinder radius="${wheel_radius}" length="${wheel_width}"/>
            </geometry>
        </collision>
        <visual>
            <origin xyz="${wheel_xgap} ${wheel_ygap} ${wheel_zoff}" rpy="0 ${PI/2} ${PI/2}"/>
            <geometry>
                <cylinder radius="${wheel_radius}" length="${wheel_width}"/>
            </geometry>
        </visual>
    </xacro:macro> -->
  <link name="chassis">
    <origin rpy="0 0 0" xyz="0.0 0.0 0"/>
    <inertial>
      <mass value="1"/>
      <inertia ixx="0.00290833217" ixy="0.0" ixz="0.0" iyy="0.01603332692" iyz="0.0" izz="0.013541661250000003"/>
    </inertial>
    <collision>
      <origin rpy="0 0 0" xyz="0.0 0.0 0"/>
      <geometry>
        <box size="0.4 0.18 0.05"/>
      </geometry>
    </collision>
    <visual>
      <origin rpy="0 0 0" xyz="0.0 0.0 0"/>
      <geometry>
        <box size="0.4 0.18 0.05"/>
      </geometry>
      <material name="grey"/>
    </visual>
  </link>
  <!-- <joint name="FR_hinge" type="continuous">
        <origin xyz="0 0 ${wheel_zoff}" rpy="0 0 0"/>
        <child link="FR_wheel"/>
        <parent link="chassis"/>
        <axis xyz="0 1 0"/>
        <dynamics damping="0.7"/>
      </joint>

    <joint name="FL_hinge" type="continuous">
        <origin xyz="0 0 ${wheel_zoff}" rpy="0 0 0 "/>
        <child link="FL_wheel"/>
        <parent link="chassis"/>
        <axis xyz="0 1 0"/>
    </joint> -->
  <joint name="BL_hinge" type="continuous">
    <origin rpy="0 0 0" xyz="-0.15 0.13 0.0"/>
    <child link="BL_wheel"/>
    <parent link="chassis"/>
    <axis xyz="0 1 0"/>
  </joint>
  <joint name="BR_hinge" type="continuous">
    <origin rpy="0 0 0" xyz="-0.15 -0.13 0.0"/>
    <child link="BR_wheel"/>
    <parent link="chassis"/>
    <axis xyz="0 1 0"/>
  </joint>
  <link name="FR_wheel">
    <inertial>
      <mass value="0.05"/>
      <origin rpy="0 1.57075 1.57075" xyz="0.15 0.13 0.0"/>
      <inertia ixx="4.166665000000001e-05" ixy="0.0" ixz="0.0" iyy="4.166665000000001e-05" iyz="0.0" izz="6.250000000000001e-05"/>
    </inertial>
    <collision>
      <origin rpy="0 1.57075 1.57075" xyz="0 0 0"/>
      <geometry>
        <cylinder length="0.05" radius="0.05"/>
      </geometry>
    </collision>
    <visual>
      <origin rpy="0 1.57075 1.57075" xyz="0 0 0"/>
      <geometry>
        <cylinder length="0.05" radius="0.05"/>
      </geometry>
      <material name="blue"/>
    </visual>
  </link>
  <link name="FL_wheel">
    <inertial>
      <mass value="0.05"/>
      <origin rpy="0 1.57075 1.57075" xyz="0 0 0"/>
      <inertia ixx="4.166665000000001e-05" ixy="0.0" ixz="0.0" iyy="4.166665000000001e-05" iyz="0.0" izz="6.250000000000001e-05"/>
    </inertial>
    <collision>
      <origin rpy="0 1.57075 1.57075" xyz="0 0 0"/>
      <geometry>
        <cylinder length="0.05" radius="0.05"/>
      </geometry>
    </collision>
    <visual>
      <origin rpy="0 1.57075 1.57075" xyz="0 0 0"/>
      <geometry>
        <cylinder length="0.05" radius="0.05"/>
      </geometry>
      <material name="blue"/>
    </visual>
  </link>
  <link name="BL_wheel">
    <inertial>
      <mass value="0.05"/>
      <origin rpy="0 1.57075 1.57075" xyz="0 0 0"/>
      <inertia ixx="4.166665000000001e-05" ixy="0.0" ixz="0.0" iyy="4.166665000000001e-05" iyz="0.0" izz="6.250000000000001e-05"/>
    </inertial>
    <collision>
      <origin rpy="0 1.57075 1.57075" xyz="0 0 0"/>
      <geometry>
        <cylinder length="0.05" radius="0.05"/>
      </geometry>
    </collision>
    <visual>
      <origin rpy="0 1.57075 1.57075" xyz="0 0 0"/>
      <geometry>
        <cylinder length="0.05" radius="0.05"/>
      </geometry>
      <material name="orange"/>
    </visual>
  </link>
  <link name="BR_wheel">
    <inertial>
      <mass value="0.05"/>
      <origin rpy="0 1.57075 1.57075" xyz="0 0 0"/>
      <inertia ixx="4.166665000000001e-05" ixy="0.0" ixz="0.0" iyy="4.166665000000001e-05" iyz="0.0" izz="6.250000000000001e-05"/>
    </inertial>
    <collision>
      <origin rpy="0 1.57075 1.57075" xyz="0 0 0"/>
      <geometry>
        <cylinder length="0.05" radius="0.05"/>
      </geometry>
    </collision>
    <visual>
      <origin rpy="0 1.57075 1.57075" xyz="0 0 0"/>
      <geometry>
        <cylinder length="0.05" radius="0.05"/>
      </geometry>
      <material name="orange"/>
    </visual>
  </link>
  <!-- <joint type="fixed" name="front_axle_joint">
        <origin xyz="0 0 0" rpy="0 0 0"/>
        <child link="Front_wheel_axles"/>
        <parent link="chassis"/>
        <axis xyz="1 0 0"/>
    </joint> -->
  <!-- <link name="Front_wheel_axles">
        <xacro:cylinder_inertial radius="${wheel_radius/10}" length="0" mass="0.01">
            <origin xyz="${wheel_xgap} 0 ${wheel_zoff}" rpy="0 ${PI/2} ${PI/2}"/>
        </xacro:cylinder_inertial>
        <visual>
            <origin xyz="${wheel_xgap} 0 ${wheel_zoff}" rpy="0 ${PI/2} ${PI/2}"/>
            <geometry>
                <cylinder radius="${wheel_radius/10}" length="${chassis_height/.9 + .1}"/>
            </geometry>
        </visual>
    </link>

    <link name="Back_wheel_axles">
        <xacro:cylinder_inertial radius="${wheel_radius/10}" length="0" mass="0.01">
            <origin xyz="${-wheel_xgap} 0 ${wheel_zoff}" rpy="0 ${PI/2} ${PI/2}"/>
        </xacro:cylinder_inertial>
        <visual>
            <origin xyz="${-wheel_xgap} 0 ${wheel_zoff}" rpy="0 ${PI/2} ${PI/2}"/>
            <geometry>
                <cylinder radius="${wheel_radius/10}" length="${chassis_height/.9 + .1}"/>
            </geometry>
        </visual>
    </link> -->
  <!-- <joint type="fixed" name="back_axle_joint">
        <child link="Back_wheel_axles"/>
        <parent link="chassis"/>
    </joint> -->
  <!-- <link name="right_wheel_assembly">
		<collision> 
            <origin xyz="0 0 0" rpy="0 ${PI/2} ${PI/2}"/>
		  <geometry> 
            <cylinder length="${wheel_width}" radius="${wheel_radius/2}"/> 
		  </geometry> 
		</collision> 

		<visual> 
            <origin xyz="0 0 0" rpy="0 ${PI/2} ${PI/2}"/>
		  <geometry> 
			<cylinder length="${wheel_width/2}" radius="${wheel_radius/2}"/> 
		  </geometry> 
		  <material name="grey"/> 
		</visual> 		

		<inertial> 
            <origin xyz="0 0 0" rpy="0 ${PI/2} ${PI/2}"/>
		  <mass value="0.2"/> 
		  <cylinder_inertia m="0.2" r="0.3" h="0.1"/> 
      <inertia ixx="0.4" ixy="0.1" ixz="0.1" iyy="0.4" iyz="0.1" izz="0.2"/> 
	  </inertial>
	</link>

    <link name="left_wheel_assembly">
		<collision> 
            <origin xyz="0 0 0" rpy="0 ${PI/2} ${PI/2}"/>
		  <geometry> 
            <cylinder length="${wheel_width}" radius="${wheel_radius/2}"/> 
		  </geometry> 
		</collision> 

		<visual> 
            <origin xyz="0 0 0" rpy="0 ${PI/2} ${PI/2}"/>
		  <geometry> 
			<cylinder length="${wheel_width/2}" radius="${wheel_radius/2}"/> 
		  </geometry> 
		  <material name="black"/> 
		</visual> 		

		<inertial> 
		  <origin xyz="0 0 0" rpy="0 ${PI/2} ${PI/2}"/>
		  <mass value="0.2"/> 
		  <cylinder_inertia m="0.2" r="0.3" h="0.1"/> 
      <inertia ixx="0.4" ixy="0.1" ixz="0.1" iyy="0.4" iyz="0.1" izz="0.2"/> 
	  </inertial>
	</link> -->
  <!-- <link name="right_wheel_assembly">
		<collision> 
            <origin xyz="0 0 0" rpy="0 ${PI/2} ${PI/2}"/>
		  <geometry> 
            <cylinder length="${wheel_width}" radius="${wheel_radius/2}"/> 
		  </geometry> 
		</collision> 

		<visual> 
            <origin xyz="0 0 0" rpy="0 ${PI/2} ${PI/2}"/>
		  <geometry> 
			<cylinder length="${wheel_width/2}" radius="${wheel_radius/2}"/> 
		  </geometry> 
		  <material name="grey"/> 
		</visual> 		

		<inertial> 
            <origin xyz="0 0 0" rpy="0 ${PI/2} ${PI/2}"/>
		  <mass value="0.2"/> 
		  <cylinder_inertia m="0.2" r="0.3" h="0.1"/> 
      <inertia ixx="0.4" ixy="0.1" ixz="0.1" iyy="0.4" iyz="0.1" izz="0.2"/> 
	  </inertial>
	</link>

    <link name="left_wheel_assembly">
		<collision> 
            <origin xyz="0 0 0" rpy="0 ${PI/2} ${PI/2}"/>
		  <geometry> 
            <cylinder length="${wheel_width}" radius="${wheel_radius/2}"/> 
		  </geometry> 
		</collision> 

		<visual> 
            <origin xyz="0 0 0" rpy="0 ${PI/2} ${PI/2}"/>
		  <geometry> 
			<cylinder length="${wheel_width/2}" radius="${wheel_radius/2}"/> 
		  </geometry> 
		  <material name="black"/> 
		</visual> 		

		<inertial> 
		  <origin xyz="0 0 0" rpy="0 ${PI/2} ${PI/2}"/>
		  <mass value="0.2"/> 
		  <cylinder_inertia m="0.2" r="0.3" h="0.1"/> 
      <inertia ixx="0.4" ixy="0.1" ixz="0.1" iyy="0.4" iyz="0.1" izz="0.2"/> 
	  </inertial>
	</link> -->
  <!-- <joint name="right_wheel_hinge" type="revolute"> 
        <parent link="chassis"/> 
        <child link="right_wheel_assembly"/> 
        <origin xyz="${wheel_xgap} ${wheel_ygap} ${wheel_zoff}" rpy="0 0 0"/> 
        <axis xyz="0 0 1" rpy="0 0 0" /> 
        <limit effort="100" velocity="1" lower="-1" upper="1"/> 
        <dynamics damping="0.0" friction="0.0"/> 
      </joint>

      <joint name="left_wheel_hinge" type="revolute"> 
        <parent link="chassis"/> 
        <child link="left_wheel_assembly"/> 
        <origin xyz="${wheel_xgap} ${-wheel_ygap} ${wheel_zoff}" rpy="0 0 0"/> 
        <axis xyz="0 0 -1" rpy="0 0 0" /> 
        <limit effort="100" velocity="1" lower="-1" upper="1"/> 
        <dynamics damping="0.0" friction="0.0"/> 
      </joint>  -->
  <!-- <joint name="steer_joint" type="revolute"> 
        <parent link="chassis"/> 
        <child link="left_wheel_assembly"/> 
        <origin xyz="${wheel_xgap} ${-wheel_ygap} ${wheel_zoff}" rpy="0 0 0"/> 
        <axis xyz="0 0 -1" rpy="0 0 0" /> 
        <limit effort="100" velocity="1" lower="-1" upper="1"/> 
        <dynamics damping="0.0" friction="0.0"/> 
      </joint>  -->
  <!-- Hokuyo Laser -->
  <link name="hokuyo_link">
    <collision>
      <origin rpy="0 0 0" xyz="0 0 0.05"/>
      <geometry>
        <box size="0.1 0.1 0.1"/>
      </geometry>
    </collision>
    <visual>
      <origin rpy="0 0 0" xyz="0 0 .05"/>
      <geometry>
        <mesh filename="hokuyo.dae"/>
      </geometry>
    </visual>
    <inertial>
      <mass value="1e-5"/>
      <origin rpy="0 0 0" xyz="0 0 0"/>
      <inertia ixx="1e-6" ixy="0" ixz="0" iyy="1e-6" iyz="0" izz="1e-6"/>
    </inertial>
  </link>
  <joint name="lidar_joint" type="fixed">
    <child link="hokuyo_link"/>
    <parent link="chassis"/>
  </joint>
  <joint name="camera_joint" type="fixed">
    <axis xyz="0 1 0"/>
    <origin rpy="0 0 0" xyz="0.1 0 .05"/>
    <parent link="chassis"/>
    <child link="camera_link"/>
  </joint>
  <!-- Camera -->
  <link name="camera_link">
    <collision>
      <origin rpy="0 0 0" xyz="0 0 0.5"/>
      <geometry>
        <box size="0.05 0.05 0.05"/>
      </geometry>
    </collision>
    <visual>
      <origin rpy="0 0 0" xyz="0 0 0"/>
      <geometry>
        <box size="0.05 0.05 0.05"/>
      </geometry>
      <material name="red"/>
    </visual>
    <inertial>
      <mass value="1e-5"/>
      <origin rpy="0 0 0" xyz="0 0 0"/>
      <inertia ixx="1e-6" ixy="0" ixz="0" iyy="1e-6" iyz="0" izz="1e-6"/>
    </inertial>
  </link>
  <!-- generate an optical frame http://www.ros.org/reps/rep-0103.html#suffix-frames
        so that ros and opencv can operate on the camera frame correctly -->
  <joint name="camera_optical_joint" type="fixed">
    <!-- these values have to be these values otherwise the gazebo camera image
            won't be aligned properly with the frame it is supposedly originating from -->
    <origin rpy="-1.5707963267948966 0 -1.5707963267948966" xyz="0 0 0"/>
    <parent link="camera_link"/>
    <child link="camera_link_optical"/>
  </joint>
  <link name="camera_link_optical">
    </link>
  <transmission name="trans_right_wheel_hing">
    <type>transmission_interface/SimpleTransmission</type>
    <joint name="right_wheel_hinge">
      <hardwareInterface>EffortJointInterface</hardwareInterface>
    </joint>
    <actuator name="motor1">
      <hardwareInterface>EffortJointInterface</hardwareInterface>
      <mechanicalReduction>1</mechanicalReduction>
    </actuator>
  </transmission>
  <transmission name="trans_right_wheel_rotate">
    <type>transmission_interface/SimpleTransmission</type>
    <joint name="right_wheel_rotate">
      <hardwareInterface>EffortJointInterface</hardwareInterface>
    </joint>
    <actuator name="motor_right_wheel_rotate">
      <hardwareInterface>EffortJointInterface</hardwareInterface>
      <mechanicalReduction>1</mechanicalReduction>
    </actuator>
  </transmission>
  <transmission name="tran2">
    <type>transmission_interface/SimpleTransmission</type>
    <joint name="left_wheel_hinge">
      <hardwareInterface>EffortJointInterface</hardwareInterface>
    </joint>
    <actuator name="motor2">
      <hardwareInterface>EffortJointInterface</hardwareInterface>
      <mechanicalReduction>1</mechanicalReduction>
    </actuator>
  </transmission>
  <transmission name="trans_left_wheel_rotate">
    <type>transmission_interface/SimpleTransmission</type>
    <joint name="left_wheel_rotate">
      <hardwareInterface>EffortJointInterface</hardwareInterface>
    </joint>
    <actuator name="motor_left_wheel_rotate">
      <hardwareInterface>EffortJointInterface</hardwareInterface>
      <mechanicalReduction>1</mechanicalReduction>
    </actuator>
  </transmission>
  <joint name="front_joint" type="fixed">
    <parent link="chassis"/>
    <child link="front_link"/>
    <origin xyz="0.16000000000000003 0.0 -0.025"/>
  </joint>
  <link name="front_link">
    <inertial>
      <mass value="1.0"/>
      <origin xyz="0 0 0"/>
      <inertia ixx="1.0" ixy="0.0" ixz="0.0" iyy="1.0" iyz="0.0" izz="1.0"/>
    </inertial>
    <visual>
      <geometry>
        <box size="0.04000000000000001 0.18 0.0005"/>
      </geometry>
      <material name="red"/>
    </visual>
    <collision>
      <geometry>
        <box size="0.04000000000000001 0.18 0.0005"/>
      </geometry>
    </collision>
  </link>
  <!-- a link aligned with the steer direction -->
  <joint name="steer_joint" type="revolute">
    <limit effort="100" lower="-0.5" upper="0.5" velocity="10"/>
    <axis xyz="0 0 1"/>
    <parent link="front_link"/>
    <child link="steer_link"/>
    <origin rpy="0 0 0" xyz="0 0.0 0.0"/>
  </joint>
  <link name="steer_link">
    <inertial>
      <mass value="1.0"/>
      <origin xyz="0 0 0"/>
      <inertia ixx="1.0" ixy="0.0" ixz="0.0" iyy="1.0" iyz="0.0" izz="1.0"/>
    </inertial>
    <visual>
      <origin xyz="-0.05 0 0"/>
      <geometry>
        <box size="0.08000000000000002 0.018 0.0005"/>
      </geometry>
      <material name="red"/>
    </visual>
    <collision>
      <origin xyz="-0.05 0 0"/>
      <geometry>
        <box size="0.08000000000000002 0.018 0.0005"/>
      </geometry>
    </collision>
  </link>
  <!-- the left Ackermann bar -->
  <joint name="front_left_bar_joint" type="revolute">
    <limit effort="100" lower="-0.5" upper="0.5" velocity="10"/>
    <axis xyz="0 0 1"/>
    <parent link="front_link"/>
    <child link="front_left_bar_link"/>
    <origin rpy="0 0 0" xyz="0.0 0.08 0.0"/>
  </joint>
  <link name="front_left_bar_link">
    <inertial>
      <mass value="1.0"/>
      <origin xyz="0 0 0"/>
      <inertia ixx="1.0" ixy="0.0" ixz="0.0" iyy="1.0" iyz="0.0" izz="1.0"/>
    </inertial>
    <visual>
      <origin xyz="-0.05 0 0"/>
      <geometry>
        <box size="0.08000000000000002 0.018 0.0005"/>
      </geometry>
      <material name="red"/>
    </visual>
    <collision>
      <origin xyz="-0.05 0 0"/>
      <geometry>
        <box size="0.08000000000000002 0.018 0.0005"/>
      </geometry>
    </collision>
  </link>
  <!-- the right Ackermann bar -->
  <joint name="front_right_bar_joint" type="revolute">
    <limit effort="100" lower="-0.5" upper="0.5" velocity="10"/>
    <axis xyz="0 0 1"/>
    <parent link="front_link"/>
    <child link="front_right_bar_link"/>
    <origin rpy="0 0 0" xyz="0.0 -0.08 0.0"/>
  </joint>
  <link name="front_right_bar_link">
    <inertial>
      <mass value="1.0"/>
      <origin xyz="0 0 0"/>
      <inertia ixx="1.0" ixy="0.0" ixz="0.0" iyy="1.0" iyz="0.0" izz="1.0"/>
    </inertial>
    <visual>
      <origin xyz="-0.05 0 0"/>
      <geometry>
        <box size="0.08000000000000002 0.018 0.0005"/>
      </geometry>
      <material name="red"/>
    </visual>
    <collision>
      <origin xyz="-0.05 0 0"/>
      <geometry>
        <box size="0.08000000000000002 0.018 0.0005"/>
      </geometry>
    </collision>
  </link>
  <!-- the front left wheel -->
  <joint name="front_left_wheel_joint" type="continuous">
    <axis xyz="0 1 0"/>
    <parent link="front_left_bar_link"/>
    <child link="FL_wheel"/>
    <origin rpy="0 0 0" xyz="0 0.05 0"/>
  </joint>
  <!-- the front right wheel -->
  <joint name="front_right_wheel_joint" type="continuous">
    <axis xyz="0 1 0"/>
    <parent link="front_right_bar_link"/>
    <child link="FR_wheel"/>
    <origin rpy="0 0 0" xyz="0 -0.05 0"/>
  </joint>
  <!-- the Ackerman bar -->
  <joint name="ackermann_joint" type="revolute">
    <limit effort="100" lower="-0.5" upper="0.5" velocity="10"/>
    <axis xyz="0 0 1"/>
    <parent link="steer_link"/>
    <child link="ackermann_bar_link"/>
    <origin rpy="0 0 0" xyz="-0.09 0 0"/>
  </joint>
  <link name="ackermann_bar_link">
    <inertial>
      <mass value="1.0"/>
      <origin xyz="0 0 0"/>
      <inertia ixx="1.0" ixy="0.0" ixz="0.0" iyy="1.0" iyz="0.0" izz="1.0"/>
    </inertial>
    <visual>
      <geometry>
        <box size="0.04000000000000001 0.18 0.0005"/>
      </geometry>
      <material name="red"/>
    </visual>
    <collision>
      <geometry>
        <box size="0.04000000000000001 0.18 0.0005"/>
      </geometry>
    </collision>
  </link>
</robot>
