<?xml version="1.0" ?>
<!-- =================================================================================== -->
<!-- |    This document was autogenerated by xacro from pedro_description/pedro.urdf.xacro | -->
<!-- |    EDITING THIS FILE BY HAND IS NOT RECOMMENDED                                 | -->
<!-- =================================================================================== -->
<robot name="Pedro">
  <!-- <xacro:macro name="wheel" params="mass radius width xgap ygap zoff reflectX reflectY">
        <xacro:cylinder_inertial radius="radius" length="width" mass="mass">
            <xacro:if value="reflectX == True">
                <origin xyz="{reflectX*xgap} ygap zoff" rpy="0 ${PI/2} ${PI/2}"/>
            </xacro:if>
            <xacro:if value="reflectY == True">
                <origin xyz="xgap {reflectY*ygap} zoff" rpy="0 ${PI/2} ${PI/2}"/>
            </xacro:if>
            <xacro:if value="reflectX == True">
                <xacro:if value="reflectY == True">
                    <origin xyz="{reflectX*xgap}  {reflectX*ygap} zoff" rpy="0 ${PI/2} ${PI/2}"/>
                </xacro:if>
            </xacro:if>
            <xacro:if value="reflectX == False">
                <xacro:if value="reflectY == False">
                    <origin xyz="{xgap}  {ygap} zoff" rpy="0 ${PI/2} ${PI/2}"/>
                </xacro:if>
            </xacro:if>
        </xacro:cylinder_inertial>
        
        <collision>
            <origin xyz="${wheel_xgap} ${wheel_ygap} ${wheel_zoff}" rpy="0 ${PI/2} ${PI/2}"/>
            <geometry>
                <cylinder radius="${wheel_radius}" length="${wheel_width}"/>
            </geometry>
        </collision>
        <visual>
            <origin xyz="${wheel_xgap} ${wheel_ygap} ${wheel_zoff}" rpy="0 ${PI/2} ${PI/2}"/>
            <geometry>
                <cylinder radius="${wheel_radius}" length="${wheel_width}"/>
            </geometry>
        </visual>
    </xacro:macro> -->
  <link name="chassis">
    <origin rpy="0 0 0" xyz="0.0 0.0 0"/>
    <inertial>
      <mass value="1"/>
      <inertia ixx="0.003541665250000001" ixy="0.0" ixz="0.0" iyy="0.016666660000000003" iyz="0.0" izz="0.013541661250000003"/>
    </inertial>
    <collision>
      <origin rpy="0 0 0" xyz="0.0 0.0 0"/>
      <geometry>
        <box size="0.4 0.2 0.05"/>
      </geometry>
    </collision>
    <visual>
      <origin rpy="0 0 0" xyz="0.0 0.0 0"/>
      <geometry>
        <box size="0.4 0.2 0.05"/>
      </geometry>
    </visual>
  </link>
  <link name="FL_wheel">
    <inertial>
      <mass value="0.05"/>
      <origin rpy="0 1.57075 1.57075" xyz="0.15 0.13 0.0"/>
      <inertia ixx="4.166665000000001e-05" ixy="0.0" ixz="0.0" iyy="4.166665000000001e-05" iyz="0.0" izz="6.250000000000001e-05"/>
    </inertial>
    <collision>
      <origin rpy="0 1.57075 1.57075" xyz="0.15 0.13 0.0"/>
      <geometry>
        <cylinder length="0.05" radius="0.05"/>
      </geometry>
    </collision>
    <visual>
      <origin rpy="0 1.57075 1.57075" xyz="0.15 0.13 0.0"/>
      <geometry>
        <cylinder length="0.05" radius="0.05"/>
      </geometry>
    </visual>
  </link>
  <link name="FR_wheel">
    <inertial>
      <mass value="0.05"/>
      <origin rpy="0 1.57075 1.57075" xyz="0.15 -0.13 0.0"/>
      <inertia ixx="4.166665000000001e-05" ixy="0.0" ixz="0.0" iyy="4.166665000000001e-05" iyz="0.0" izz="6.250000000000001e-05"/>
    </inertial>
    <collision>
      <origin rpy="0 1.57075 1.57075" xyz="0.15 -0.13 0.0"/>
      <geometry>
        <cylinder length="0.05" radius="0.05"/>
      </geometry>
    </collision>
    <visual>
      <origin rpy="0 1.57075 1.57075" xyz="0.15 -0.13 0.0"/>
      <geometry>
        <cylinder length="0.05" radius="0.05"/>
      </geometry>
    </visual>
  </link>
  <link name="BL_wheel">
    <inertial>
      <mass value="0.05"/>
      <origin rpy="0 1.57075 1.57075" xyz="-0.15 0.13 0.0"/>
      <inertia ixx="4.166665000000001e-05" ixy="0.0" ixz="0.0" iyy="4.166665000000001e-05" iyz="0.0" izz="6.250000000000001e-05"/>
    </inertial>
    <collision>
      <origin rpy="0 1.57075 1.57075" xyz="-0.15 0.13 0.0"/>
      <geometry>
        <cylinder length="0.05" radius="0.05"/>
      </geometry>
    </collision>
    <visual>
      <origin rpy="0 1.57075 1.57075" xyz="-0.15 0.13 0.0"/>
      <geometry>
        <cylinder length="0.05" radius="0.05"/>
      </geometry>
    </visual>
  </link>
  <link name="BR_wheel">
    <inertial>
      <mass value="0.05"/>
      <origin rpy="0 1.57075 1.57075" xyz="-0.15 -0.13 0.0"/>
      <inertia ixx="4.166665000000001e-05" ixy="0.0" ixz="0.0" iyy="4.166665000000001e-05" iyz="0.0" izz="6.250000000000001e-05"/>
    </inertial>
    <collision>
      <origin rpy="0 1.57075 1.57075" xyz="-0.15 -0.13 0.0"/>
      <geometry>
        <cylinder length="0.05" radius="0.05"/>
      </geometry>
    </collision>
    <visual>
      <origin rpy="0 1.57075 1.57075" xyz="-0.15 -0.13 0.0"/>
      <geometry>
        <cylinder length="0.05" radius="0.05"/>
      </geometry>
    </visual>
  </link>
  <link name="Front_wheel_axles">
    <inertial>
      <mass value="0.01"/>
      <origin rpy="0 1.57075 1.57075" xyz="0.15 0 0.0"/>
      <inertia ixx="6.2499975e-08" ixy="0.0" ixz="0.0" iyy="6.2499975e-08" iyz="0.0" izz="1.2500000000000002e-07"/>
    </inertial>
    <visual>
      <origin rpy="0 1.57075 1.57075" xyz="0.15 0 0.0"/>
      <geometry>
        <cylinder length="0.22222222222222224 + .1" radius="0.005"/>
      </geometry>
    </visual>
  </link>
  <joint name="front_axle_joint" type="fixed">
    <child link="Front_wheel_axles"/>
    <parent link="chassis"/>
  </joint>
  <joint name="FL_hinge" type="continuous">
    <origin rpy="0 0 0" xyz="0 0 0"/>
    <child link="FL_wheel"/>
    <parent link="Front_wheel_axles"/>
    <axis xyz="0 1 0"/>
  </joint>
  <joint name="FR_hinge" type="continuous">
    <origin rpy="0 0 0" xyz="0.15 -0.13 0.0"/>
    <child link="FR_wheel"/>
    <parent link="chassis"/>
    <axis xyz="0 1 0"/>
  </joint>
  <joint name="BL_hinge" type="continuous">
    <origin rpy="0 0 0" xyz="0 0 0.0"/>
    <child link="BL_wheel"/>
    <parent link="chassis"/>
    <axis xyz="0 1 0"/>
  </joint>
  <joint name="BR_hinge" type="continuous">
    <origin rpy="0 0 0" xyz="0 0 0.0"/>
    <child link="BR_wheel"/>
    <parent link="chassis"/>
    <axis xyz="0 1 0"/>
  </joint>
  <!-- <include>
        <uri>model://hokuyo</uri>
        <pose>0.2 0 0.2 0 0 0</pose>
    </include>
    <joint name="hokuyo_joint" type="fixed">
        <child>hokuyo::link</child>
        <parent>chassis</parent>
    </joint> -->
</robot>
